Workbook

Sheet 组合
DU1: 1 | DV1: 3 | DW1: 5 | DX1: 6 | DY1: 7 | DZ1: 11 | EA1: 13 | EB1: 15 | EC1: 16 | ED1: 21 | EE1: 23 | EF1: 24 | EG1: 25 | EH1: 29 | EI1: 31 | EJ1: 32 | EK1: 33 | EL1: 35 | EM1: 37 | EN1: 38 | EO1: 39 | EP1: 41 | EQ1: 45 | ER1: 47 | ES1: 48 | ET1: 52 | EU1: 61 | EX1: 其中，最优的往往是15、21、23、24、25、29、31、32、37、41等，适合人格或总格
G2: 用字五行
A3: 总格 | B3: 人格 | C3: 地格 | D3: 三格五行 | E3: 字 | F3: 笔画 | G3: 火 | U3: 土 | AN3: 金 | BI3: 水 | CU3: 木 | DS3: 木 | EB3: 金 | EM3: 火 | EX3: 土 | FD3: 水
A4: =F4+F5+F6 -> 41 | B4: =F4+F5 -> 31 | C4: =F5+F6 -> 25 | D4: 金 | E4: 姓 | F4: 16
D5: 木 | E5: 名 | F5: 15 | G5: =字!B10 -> 瑾 | H5: =字!C10 -> 熠 | I5: =字!D10 -> 飘 | J5: =字!E10 -> 璋 | K5: =字!F10 -> 璇 | L5: =字!G10 -> 乐 | M5: =字!H10 -> 黎 | N5: =字!I10 -> 0 | O5: =字!J10 -> 0 | P5: =字!AJ10 -> 0 | U5: =字!AK10 -> 璎 | V5: =字!AL10 -> 娴 | W5: =字!AM10 -> 頤 | X5: =字!AN10 -> 0 | Y5: =字!AO10 -> 0 | Z5: =字!AP10 -> 0 | AA5: =字!AQ10 -> 0 | AB5: =字!AR10 -> 0 | AC5: =字!AS10 -> 0 | AN5: =字!BK10 -> 聪 | AO5: =字!BL10 -> 璀 | AP5: =字!BM10 -> 颛 | AQ5: =字!BN10 -> 璁 | AR5: =字!BO10 -> 赜 | AS5: =字!BP10 -> 暹 | AT5: =字!BQ10 -> 婵 | AU5: =字!BR10 -> 鋆 | AV5: =字!BT10 -> 0 | AW5: =字!DC10 -> 0 | BI5: =字!DD10 -> 慧 | BJ5: =字!DE10 -> 澄 | BK5: =字!DF10 -> 霄 | BL5: =字!DG10 -> 勰 | BM5: =字!DH10 -> 0 | BN5: =字!DI10 -> 0 | CT5: =字!DJ10 -> 0 | CU5: =字!EI10 -> 萱 | CV5: =字!EJ10 -> 蕴 | CW5: =字!EK10 -> 蕙 | CX5: =字!EL10 -> 憬 | CY5: =字!EM10 -> 樱 | CZ5: =字!EN10 -> 樊 | DA5: =字!EO10 -> 0 | DB5: =字!EP10 -> 0 | DC5: =字!EQ10 -> 0
D6: 土 | F6: 10
A8: =F8+F9+F10 -> 41 | B8: =F8+F9 -> 25 | C8: =F9+F10 -> 25 | D8: 金 | E8: 姓 | F8: 16
D9: 土 | E9: 名 | F9: 9 | G9: 映 | H9: 亮 | I9: 昱 | J9: 貞 | K9: 昭 | L9: 炫 | M9: 亭 | N9: 恺 | O9: 珏 | U9: 胡 | V9: 禹 | W9: 玥 | X9: 音 | Y9: 姻 | Z9: 怡 | AA9: 宥 | AB9: 爰 | AN9: 勅 | AO9: 柔 | AP9: 思 | AQ9: 宣 | AR9: 星 | AS9: 胜
D10: 土 | F10: 16 | G10: 璇 | H10: 乐 | I10: 骆 | J10: 熹 | K10: 晓 | L10: 昙 | M10: 谘 | N10: 达 | O10: 陵 | U10: 蓉 | V10: 谙 | W10: 遐 | X10: 谓 | Y10: 壁 | Z10: 嫒
A12: =F12+F13+F14 -> 31 | B12: =F12+F13 -> 25 | C12: =F13+F14 -> 15 | D12: 金 | E12: 姓 | F12: 16
D13: 土 | E13: 名 | F13: 9 | G13: 映 | H13: 亮 | I13: 昱 | J13: 貞 | K13: 昭 | L13: 炫 | M13: 亭 | N13: 恺 | O13: 珏 | P13: 朎 | Q13: 穾 | U13: 胡 | V13: 禹 | W13: 玥 | X13: 音 | Y13: 姻 | Z13: 怡 | AA13: 宥 | AB13: 爰 | AC13: 姚 | AD13: 禹 | AN13: 勅 | AO13: 柔 | AP13: 思 | AQ13: 宣 | AR13: 星 | AS13: 胜 | AT13: 咨 | AU13: 姹 | AV13: 姿 | AW13: 姝 | AX13: 施 | AY13: 冑 | BI13: 宪 | BJ13: 咸 | BK13: 敃 | BL13: 畈 | BM13: 盈 | BN13: 盼 | BO13: 砇 | BP13: 竼 | BQ13: 美 | BR13: 飛 | BS13: 香 | BT13: 匍 | BU13: 品 | BV13: 奔 | BW13: 奐 | BX13: 姵 | BY13: 姳 | BZ13: 封 | CA13: 屏 | CB13: 峚 | CC13: 巷 | CD13: 弭 | CE13: 怤 | CF13: 扁 | CG13: 柎 | CH13: 毘 | CI13: 毗 | CJ13: 泳 | CK13: 泉 | CL13: 玅 | CM13: 玭 | CN13: 畆 | CO13: 畈 | CP13: 竑 | CQ13: 笀 | CR13: 紅 | CS13: 計 | CU13: 冠 | CV13: 奕 | CW13: 姬 | CX13: 姣 | CY13: 姜 | CZ13: 彥 | DA13: 柏 | DB13: 柠 | DC13: 皆 | DD13: 相 | DE13: 矜 | DF13: 祈 | DG13: 羿 | DH13: 芕 | DI13: 芅 | DJ13: 芍 | DK13: 赳 | DL13: 垎 | DM13: 契 | DN13: 姽 | DO13: 姤 | DP13: 姯 | DQ13: 姮 | DR13: 姱 | DS13: 峆 | DT13: 峘 | DU13: 建 | DV13: 弈 | DW13: 敂 | DX13: 斫 | DY13: 枽 | DZ13: 枼 | EA13: 柃 | EB13: 柄 | EC13: 柍 | ED13: 柑 | EE13: 柘 | EF13: 柚 | EG13: 柢 | EH13: 柭 | EI13: 柯 | EJ13: 柱 | EK13: 柳 | EL13: 枹 | EM13: 牁 | EN13: 牱 | EO13: 牮 | EP13: 界 | EQ13: 癸 | ER13: 皆 | ES13: 皈 | ET13: 禺 | EU13: 竽 | EV13: 紇 | EW13: 紀 | EX13: 羍 | EY13: 肖 | EZ13: 酋
D14: 土 | F14: 6 | G14: 光 | H14: 多 | I14: 年 | J14: 亘 | K14: 囡 | L14: 旨 | M14: 弛 | U14: 安 | V14: 宇 | W14: 伊 | X14: 亦 | Y14: 圳 | Z14: 伟 | AA14: 有 | AB14: 艮 | AC14: 羽 | AD14: 因 | AE14: 旬 | AF14: 圭 | AG14: 地 | AH14: 圪 | AM14: 屹 | AN14: 如 | AO14: 此 | AP14: 舟 | AQ14: 齐 | AR14: 刚 | AS14: 任 | AT14: 丞 | AU14: 夙 | AV14: 存 | AW14: 早 | AX14: 旬 | AY14: 吏 | AZ14: 咨 | BI14: 好 | BJ14: 帆 | BK14: 合 | BL14: 冰 | BM14: 米 | BN14: 竹 | BO14: 旭 | BP14: 勉 | BQ14: 厚 | BR14: 印 | BS14: 叒 | BT14: 向 | BU14: 后 | BV14: 名 | BW14: 妃 | BX14: 払 | BY14: 收 | BZ14: 牝 | CA14: 牟 | CB14: 百 | CU14: 朵 | CV14: 吉 | CW14: 权 | CX14: 共 | CY14: 曲 | CZ14: 企 | DA14: 匡 | DB14: 聿 | DC14: 朴 | DD14: 巩 | DE14: 朱 | DF14: 妅 | DG14: 劥 | DH14: 匢 | DI14: 匡 | DJ14: 各 | DK14: 夸 | DL14: 巟 | DM14: 幵 | DN14: 戎 | DO14: 攷 | DP14: 机
A16: =F16+F17+F18 -> 37 | B16: =F16+F17 -> 21 | C16: =F17+F18 -> 21 | D16: 金 | E16: 姓 | F16: 16
D17: 木 | E17: 名 | F17: 5 | G17: 令 | H17: 冉 | I17: 宁 | J17: 奵 | K17: 尔 | L17: 尼 | M17: 叮 | U17: 尓 | V17: 幼 | W17: 叶 | X17: 右 | AN17: 司 | AO17: 厇 | BI17: 丕 | BJ17: 外 | BK17: 平 | BL17: 布 | BM17: 乎 | CU17: 功 | CV17: 巧 | CW17: 巨 | CX17: 可 | CY17: 古 | CZ17: 卉 | DA17: 丘
D18: 木 | F18: 16 | U18: 融 | V18: 衡 | AN18: 静 | BI18: 学 | BJ18: 悯 | BK18: 霖 | BL18: 霓 | BM18: 霍 | BN18: 霏 | BO18: 蒙 | BP18: 潘
A20: =F20+F21+F22 -> 29 | B20: =F20+F21 -> 23 | C20: =F21+F22 -> 13 | D20: 金 | E20: 姓 | F20: 16
D21: 火 | E21: 名 | F21: 7
D22: 火 | F22: 6
A24: =F24+F25+F26 -> 31 | B24: =F24+F25 -> 24 | C24: =F25+F26 -> 15 | D24: 金 | E24: 姓 | F24: 16
D25: 火 | E25: 名 | F25: 8
D26: 土 | F26: 7 | U26: 延 | AY26: 礽 | BK26: 汎 | BL26: 汝 | BP26: 汐 | BQ26: 汕
A28: =F28+F29+F30 -> 29 | B28: =F28+F29 -> 24 | C28: =F29+F30 -> 13 | D28: 金 | E28: 姓 | F28: 16
D29: 火 | E29: 名 | F29: 8
D30: 火 | F30: 5
A32: =F32+F33+F34 -> 39 | B32: =F32+F33 -> 24 | C32: =F33+F34 -> 23 | D32: 金 | E32: 姓 | F32: 16
D33: 火 | E33: 名 | F33: 8
D34: 火 | F34: 15 | BI34: 兴 | BJ34: 霈
A36: =F36+F37+F38 -> 47 | B36: =F36+F37 -> 24 | C36: =F37+F38 -> 31 | D36: 金 | E36: 姓 | F36: 16
D37: 火 | E37: 名 | F37: 8
D38: 木 | F38: 23
A40: =F40+F41+F42 -> 29 | B40: =F40+F41 -> 25 | C40: =F41+F42 -> 13 | D40: 金 | E40: 姓 | F40: 16
D41: 土 | E41: 名 | F41: 9
D42: 火 | F42: 4 | G42: 丹 | H42: 斗 | I42: 长 | J42: 仑 | K42: 天 | L42: 中 | M42: 丰 | N42: 邓
A44: =F44+F45+F46 -> 31 | B44: =F44+F45 -> 29 | C44: =F45+F46 -> 15 | D44: 金 | E44: 姓 | F44: 16
D45: 水 | E45: 名 | F45: 13
D46: 土 | F46: 2
A48: =F48+F49+F50 -> 37 | B48: =F48+F49 -> 31 | C48: =F49+F50 -> 21 | D48: 金 | E48: 姓 | F48: 16
D49: 木 | E49: 名 | F49: 15
D50: 木 | F50: 6
A52: =F52+F53+F54 -> 47 | B52: =F52+F53 -> 32 | C52: =F53+F54 -> 31 | D52: 金 | E52: 姓 | F52: 16
...

Sheet 字
A1: 笔画 | B1: 火 | AK1: 土 | BK1: 金 | DD1: 水 | EI1: 木
A2: 4 | B2: 丹 | C2: 斗 | D2: 长 | E2: 仑 | F2: 天 | G2: 中 | H2: 丰 | I2: 邓 | J2: 从 | K2: 支 | L2: 井 | M2: 午 | N2: 厅 | O2: 订 | P2: 太 | Q2: 日 | R2: 六 | S2: 屯 | T2: 火 | U2: 内 | V2: 历 | W2: 队 | AK2: 韦 | AL2: 忆 | AM2: 友 | AN2: 允 | AO2: 尹 | AP2: 尤 | AQ2: 王 | AR2: 引 | AS2: 予 | BK2: 心 | BL2: 书 | BM2: 升 | BN2: 仁 | BO2: 专 | BP2: 少 | BQ2: 车 | DD2: 文 | DE2: 风 | DF2: 云 | DG2: 幻 | DH2: 方 | DI2: 凤 | DJ2: 贝 | DK2: 化 | DL2: 计 | DM2: 毛 | DN2: 户 | DO2: 冈 | DP2: 壬 | DQ2: 巴 | DR2: 办 | DS2: 比 | DT2: 夫 | DU2: 互 | DV2: 水 | EI2: 月 | EJ2: 介 | EK2: 艺 | EL2: 今 | EM2: 元 | EN2: 牙 | EO2: 见 | EP2: 孔 | EQ2: 区 | ER2: 公 | ES2: 匀 | ET2: 亢 | EU2: 巨 | EV2: 开
A3: 5 | B3: 礼 | C3: 冬 | D3: 宁 | E3: 冉 | F3: 丛 | G3: 令 | H3: 田 | I3: 厉 | J3: 讯 | K3: 尼 | L3: 卢 | M3: 辽 | N3: 代 | O3: 立 | P3: 让 | Q3: 左 | R3: 讨 | S3: 旦 | T3: 对 | U3: 只 | V3: 台 | W3: 头 | X3: 丙 | Y3: 召 | Z3: 另 | AA3: 叹 | AB3: 尔 | AC3: 电 | AK3: 永 | AL3: 圣 | AM3: 叶 | AN3: 艾 | AO3: 仔 | AP3: 戊 | AQ3: 央 | AR3: 鸟 | AS3: 右 | AT3: 由 | AU3: 幼 | AV3: 孕 | AW3: 用 | BK3: 正 | BL3: 生 | BM3: 仙 | BN3: 丝 | BO3: 石 | BP3: 仟 | BQ3: 仕 | BR3: 四 | BS3: 阡 | BT3: 出 | BU3: 史 | BV3: 仞 | BW3: 戋 | BX3: 帅 | BY3: 司 | BZ3: 册 | CA3: 节 | CB3: 处 | CC3: 闪 | CD3: 市 | CE3: 讪 | CF3: 占 | CG3: 刊 | CH3: 世 | CI3: 且 | CJ3: 主 | CK3: 示 | CL3: 叱 | CM3: 礼 | CN3: 矢 | CO3: 刍 | DD3: 白 | DE3: 民 | DF3: 发 | DG3: 平 | DH3: 禾 | DI3: 汇 | DJ3: 印 | DK3: 汉 | DL3: 必 | DM3: 写 | DN3: 务 | DO3: 弘 | DP3: 皮 | DQ3: 训 | DR3: 半 | DS3: 冯 | DT3: 玄 | DU3: 付 | DV3: 北 | DW3: 目 | DX3: 汀 | DY3: 弁 | DZ3: 号 | EA3: 布 | EB3: 丕 | EC3: 邙 | ED3: 邗 | EE3: 包 | EF3: 末兄 | EG3: 边 | EI3: 东 | EJ3: 甘 | EK3: 兰 | EL3: 卉 | EM3: 仪 | EN3: 巧 | EO3: 功 | EP3: 未 | EQ3: 加 | ER3: 玉 | ES3: 业 | ET3: 击 | EU3: 可 | EV3: 瓜 | EW3: 卡 | EX3: 邝 | EY3: 丘 | EZ3: 本 | FA3: 古 | FB3: 甲 | FC3: 卯 | FD3: 议 | FE3: 术 | FF3: 驭 | FG3: 归 | FH3: 外 | FI3: 句 | FJ3: 札 | FK3: 纠
A4: 6 | B4: 光 | C4: 多 | D4: 年 | E4: 亘 | AK4: 安 | AL4: 宇 | AM4: 伊 | AN4: 亦 | AO4: 圳 | AP4: 伟 | AQ4: 有 | AR4: 艮 | AS4: 羽 | AT4: 延 | BK4: 如 | BL4: 此 | BM4: 舟 | BN4: 齐 | BO4: 刚 | BP4: 任 | BQ4: 丞 | BT4: 页 | BU4: 臣 | BV4: 先 | BW4: 列 | BX4: 早 | BY4: 壮 | BZ4: 冲 | CA4: 再 | CB4: 伫 | CC4: 曳 | CD4: 西 | CE4: 则 | CF4: 守 | CG4: 而 | CH4: 众 | CI4: 存 | CK4: 创 | CL4: 庄 | CM4: 旬 | CN4: 产 | CO4: 纤 | CP4: 寺 | CQ4: 问 | CR4: 岁 | CS4: 字 | CT4: 迁 | CU4: 设 | CV4: 巡 | CW4: 划 | CX4: 孙 | CY4: 夙 | CZ4: 忖 | DA4: 妁 | DD4: 朵 | DE4: 竹 | DF4: 吉 | DG4: 曲 | DH4: 朱 | DI4: 芝 | DJ4: 仰 | DK4: 任 | DL4: 共 | DM4: 芒 | EI4: 旭 | EJ4: 朵 | EK4: 乔 | EL4: 曲 | EM4: 吉 | EN4: 戎 | EO4: 芊 | EP4: 庆 | EQ4: 芝 | ER4: 祁 | ES4: 尧 | ET4: 芍 | EU4: 权 | EV4: 件 | EW4: 军 | EX4: 巩 | EY4: 竹 | EZ4: 肌 | FA4: 朱 | FB4: 芃 | FC4: 企 | FD4: 芒 | FE4: 伉 | FF4: 仰 | FG4: 纪 | FH4: 级 | FI4: 阮 | FJ4: 许 | FK4: 关 | FL4: 聿 | FM4: 交 | FN4: 芋 | FO4: 过 | FP4: 扩 | FQ4: 匡 | FR4: 阶 | FS4: 讲 | FT4: 夸 | FU4: 玑 | FV4: 共 | FW4: 机 | FX4: 芄 | FY4: 芎 | FZ4: 朴 | GA4: 观 | GB4: 考
A5: 7 | B5: 彤
A6: 8
A7: 9 | B7: 映 | C7: 亮 | D7: 昱 | E7: 貞 | F7: 昭 | G7: 炫 | H7: 亭 | I7: 恺 | J7: 珏 | M7: 俊 | N7: 炳 | O7: 祝 | P7: 昭 | Q7: 炯 | S7: 俪 | T7: 显 | V7: 炽 | W7: 政 | Z7: 将 | AA7: 南 | AC7: 郦 | AD7: 重 | AE7: 律 | AF7: 段 | AK7: 胡 | AL7: 禹 | AM7: 玥 | AN7: 音 | AO7: 姻 | AP7: 怡 | AQ7: 宥 | AR7: 爰 | BK7: 勅 | BL7: 柔 | BM7: 思 | BN7: 宣 | BO7: 星 | BP7: 胜 | BR7: 秋 | BT7: 钥 | BU7: 施 | BV7: 祖 | BW7: 顺 | BX7: 钧 | BY7: 春 | BZ7: 战 | CA7: 信 | CB7: 修 | CC7: 钢 | CD7: 咨 | CE7: 姿 | CF7: 胥 | CG7: 珄 | CH7: 玿 | CI7: 钟 | CJ7: 俞 | CK7: 总 | CL7: 神 | CM7: 甚 | CN7: 剑 | CO7: 姝 | CP7: 省 | CQ7: 逊 | CR7: 兹 | CS7: 独
A8: 10 | J8: 玲 | K8: 娜 | O8: 祝 | R8: 珍 | X8: 庭 | BQ8: 珊
A9: 12 | Y9: 轶 | AO9: 勋 | BS9: 钦
A10: 15 | B10: 瑾 | C10: 熠 | D10: 飘 | E10: 璋 | F10: 璇 | G10: 乐 | H10: 黎 | AK10: 璎 | AL10: 娴 | AM10: 頤 | BK10: 聪 | BL10: 璀 | BM10: 颛 | BN10: 璁 | BO10: 赜 | BP10: 暹 | BQ10: 婵 | BR10: 鋆 | DD10: 慧 | DE10: 澄 | DF10: 霄 | DG10: 勰 | EI10: 萱 | EJ10: 蕴 | EK10: 蕙 | EL10: 憬 | EM10: 樱 | EN10: 樊
A11: 16 | B11: 璇 | C11: 乐 | D11: 骆 | E11: 熹 | F11: 晓 | G11: 昙 | H11: 谘 | I11: 达 | J11: 陵 | AK11: 蓉 | AL11: 谙 | AM11: 遐 | AN11: 谓 | AO11: 壁 | AP11: 嫒
